{"uuid": "72004bfb-5b3e-4429-9d84-787a971152af", "children": ["cd131891-72ba-48db-b828-2c06ab9d02c3", "1a15fab9-0f53-4450-a43d-248b3597af3f", "f777e87c-5f7f-4132-a467-46824420475c"], "befores": [{"name": "init_get_request", "status": "broken", "statusDetails": {"message": "requests.exceptions.ConnectionError: HTTPConnectionPool(host='localhost', port=8080): Max retries exceeded with url: /api/v3/work_packages/34 (Caused by NewConnectionError('<urllib3.connection.HTTPConnection object at 0x0000023FCFD378E0>: Failed to establish a new connection: [WinError 10061] No connection could be made because the target machine actively refused it'))\n", "trace": "  File \"C:\\Users\\nirel\\AppData\\Local\\Programs\\Python\\Python38\\lib\\site-packages\\pluggy\\callers.py\", line 187, in _multicall\n    res = hook_impl.function(*args)\n  File \"C:\\Users\\nirel\\AppData\\Local\\Programs\\Python\\Python38\\lib\\site-packages\\_pytest\\fixtures.py\", line 1126, in pytest_fixture_setup\n    result = call_fixture_func(fixturefunc, request, kwargs)\n  File \"C:\\Users\\nirel\\AppData\\Local\\Programs\\Python\\Python38\\lib\\site-packages\\_pytest\\fixtures.py\", line 932, in call_fixture_func\n    fixture_result = fixturefunc(**kwargs)\n  File \"C:\\Programming\\Automation\\Project\\apiTesting\\tests\\test_5.py\", line 13, in init_get_request\n    response = ProjectApi().get_work_package_by_id(self.work_package_id)\n  File \"C:\\Programming\\Automation\\Project\\apiTesting\\api\\project_api.py\", line 45, in get_work_package_by_id\n    response = super().get(path=f\"/api/v3/work_packages/{work_package_id}\")\n  File \"C:\\Programming\\Automation\\Project\\apiTesting\\api\\rest_client.py\", line 16, in get\n    response = requests.request(\"GET\", url=self.__base_url + path, headers=self.__headers)\n  File \"C:\\Users\\nirel\\AppData\\Local\\Programs\\Python\\Python38\\lib\\site-packages\\requests\\api.py\", line 61, in request\n    return session.request(method=method, url=url, **kwargs)\n  File \"C:\\Users\\nirel\\AppData\\Local\\Programs\\Python\\Python38\\lib\\site-packages\\requests\\sessions.py\", line 542, in request\n    resp = self.send(prep, **send_kwargs)\n  File \"C:\\Users\\nirel\\AppData\\Local\\Programs\\Python\\Python38\\lib\\site-packages\\requests\\sessions.py\", line 655, in send\n    r = adapter.send(request, **kwargs)\n  File \"C:\\Users\\nirel\\AppData\\Local\\Programs\\Python\\Python38\\lib\\site-packages\\requests\\adapters.py\", line 516, in send\n    raise ConnectionError(e, request=request)\n"}, "start": 1625586294629, "stop": 1625586298635}], "start": 1625586294629, "stop": 1625586311613}