{"uuid": "3fcc695a-4089-4b1b-b2a0-ffcee1854ed1", "children": ["7e80da6b-fc9c-4e12-bd2a-616f99ddbcce", "f3c6acdf-0808-42cf-87f5-52ee473d3133"], "befores": [{"name": "init_patch_request", "status": "broken", "statusDetails": {"message": "requests.exceptions.ConnectionError: HTTPConnectionPool(host='localhost', port=8080): Max retries exceeded with url: /api/v3/projects/3 (Caused by NewConnectionError('<urllib3.connection.HTTPConnection object at 0x0000023FCFF552E0>: Failed to establish a new connection: [WinError 10061] No connection could be made because the target machine actively refused it'))\n", "trace": "  File \"C:\\Users\\nirel\\AppData\\Local\\Programs\\Python\\Python38\\lib\\site-packages\\pluggy\\callers.py\", line 187, in _multicall\n    res = hook_impl.function(*args)\n  File \"C:\\Users\\nirel\\AppData\\Local\\Programs\\Python\\Python38\\lib\\site-packages\\_pytest\\fixtures.py\", line 1126, in pytest_fixture_setup\n    result = call_fixture_func(fixturefunc, request, kwargs)\n  File \"C:\\Users\\nirel\\AppData\\Local\\Programs\\Python\\Python38\\lib\\site-packages\\_pytest\\fixtures.py\", line 932, in call_fixture_func\n    fixture_result = fixturefunc(**kwargs)\n  File \"C:\\Programming\\Automation\\Project\\apiTesting\\tests\\test_2.py\", line 12, in init_patch_request\n    response = ProjectApi().patch_project_description(self.project_id, self.new_description)\n  File \"C:\\Programming\\Automation\\Project\\apiTesting\\api\\project_api.py\", line 24, in patch_project_description\n    response = super().patch(path=f\"/api/v3/projects/{project_id}\", payload=payload)\n  File \"C:\\Programming\\Automation\\Project\\apiTesting\\api\\rest_client.py\", line 21, in patch\n    response = requests.request(\"PATCH\", url=self.__base_url + path, headers=self.__headers, data=payload)\n  File \"C:\\Users\\nirel\\AppData\\Local\\Programs\\Python\\Python38\\lib\\site-packages\\requests\\api.py\", line 61, in request\n    return session.request(method=method, url=url, **kwargs)\n  File \"C:\\Users\\nirel\\AppData\\Local\\Programs\\Python\\Python38\\lib\\site-packages\\requests\\sessions.py\", line 542, in request\n    resp = self.send(prep, **send_kwargs)\n  File \"C:\\Users\\nirel\\AppData\\Local\\Programs\\Python\\Python38\\lib\\site-packages\\requests\\sessions.py\", line 655, in send\n    r = adapter.send(request, **kwargs)\n  File \"C:\\Users\\nirel\\AppData\\Local\\Programs\\Python\\Python38\\lib\\site-packages\\requests\\adapters.py\", line 516, in send\n    raise ConnectionError(e, request=request)\n"}, "start": 1625586281999, "stop": 1625586286008}], "start": 1625586281999, "stop": 1625586311615}